<?xml version="1.0"?>
<robot name="visual">

  <material name="blue">
    <color rgba="0 0 0.8 1"/>
  </material>
  <material name="black">
    <color rgba="0 0 0 1"/>
  </material>
  <material name="white">
    <color rgba="1 1 1 1"/>
  </material>

  <link name="base_link">
    <visual>
      <geometry>
        <box size="0.1 0.4 0.5"/>
      </geometry>
      <material name="blue"/>
    </visual>
  </link>


  <link name="index_phalanx_base">
    <visual>
      <geometry>
        <cylinder length="0.1" radius="0.02"/>
      </geometry>
      <origin xyz="0 0.0 0.05"/>
      <material name="white"/>
    </visual>
  </link>

  <link name="index_phalanx_2">
    <visual>
      <geometry>
        <cylinder length="0.1" radius="0.02"/>
      </geometry>
      <material name="blue"/>
       <origin xyz="0 0.0 0.05"/>
    </visual>
  </link>

  <link name="index_phalanx_3">
    <visual>
      <geometry>
        <cylinder length="0.1" radius="0.02"/>
      </geometry>
      <material name="white"/>
       <origin xyz="0 0.0 0.05"/>
    </visual>
  </link>


  <joint name="index_phalanx_base_joint" type="revolute">
    <axis xyz="0 1 0"/>
    <limit effort="1000.0" lower="0.0" upper="1" velocity="0.5"/>
    <parent link="base_link"/>
    <child link="index_phalanx_base"/>
    <origin xyz="0 0.17 0.25"/>
  </joint>
  <joint name="index_phalanx_2_joint" type="revolute">
    <axis xyz="0 1 0"/>
    <limit effort="1000.0" lower="0.0" upper="1" velocity="0.5"/>
    <parent link="index_phalanx_base"/>
    <child link="index_phalanx_2"/>
    <origin xyz="0 0 0.1"/>
   
  </joint>

  <joint name="index_phalanx_3_joint" type="revolute">
    <axis xyz="0 1 0"/>
    <limit effort="1000.0" lower="0.0" upper="1" velocity="0.5"/>
    <parent link="index_phalanx_2"/>
    <child link="index_phalanx_3"/>
    <origin xyz="0 0 0.1"/>
   
  </joint>



  <!--second finger-->
  <link name="second_finger_phalanx_base">
    <visual>
      <geometry>
        <cylinder length="0.1" radius="0.02"/>
      </geometry>
      <origin xyz="0 0.0 0.05"/>
      <material name="white"/>
    </visual>
  </link>

  <link name="second_finger_phalanx_2">
    <visual>
      <geometry>
        <cylinder length="0.1" radius="0.02"/>
      </geometry>
      <material name="blue"/>
       <origin xyz="0 0.0 0.05"/>
    </visual>
  </link>

  <link name="second_finger_phalanx_3">
    <visual>
      <geometry>
        <cylinder length="0.1" radius="0.02"/>
      </geometry>
      <material name="white"/>
       <origin xyz="0 0.0 0.05"/>
    </visual>
  </link>


  <joint name="second_finger_phalanx_base_joint" type="revolute">
    <axis xyz="0 1 0"/>
    <limit effort="1000.0" lower="0.0" upper="1" velocity="0.5"/>
    <parent link="base_link"/>
    <child link="second_finger_phalanx_base"/>
    <origin xyz="0 0.05 0.25"/>
  </joint>
  <joint name="second_finger_phalanx_2_joint" type="revolute">
    <axis xyz="0 1 0"/>
    <limit effort="1000.0" lower="0.0" upper="1" velocity="0.5"/>
    <parent link="second_finger_phalanx_base"/>
    <child link="second_finger_phalanx_2"/>
    <origin xyz="0 0 0.1"/>
   
  </joint>

  <joint name="second_finger_phalanx_3_joint" type="revolute">
    <axis xyz="0 1 0"/>
    <limit effort="1000.0" lower="0.0" upper="1" velocity="0.5"/>
    <parent link="second_finger_phalanx_2"/>
    <child link="second_finger_phalanx_3"/>
    <origin xyz="0 0 0.1"/>
   
  </joint>


  <!--third finger-->
  <link name="third_finger_phalanx_base">
    <visual>
      <geometry>
        <cylinder length="0.1" radius="0.02"/>
      </geometry>
      <origin xyz="0 0.00 0.05"/>
      <material name="white"/>
    </visual>
  </link>

  <link name="third_finger_phalanx_2">
    <visual>
      <geometry>
        <cylinder length="0.1" radius="0.02"/>
      </geometry>
      <material name="blue"/>
      <origin xyz="0 0.0 0.05"/>
    </visual>
  </link>

  <link name="third_finger_phalanx_3">
    <visual>
      <geometry>
        <cylinder length="0.1" radius="0.02"/>
      </geometry>
      <material name="white"/>
      <origin xyz="0 0.0 0.05"/>
    </visual>
  </link>

  <joint name="third_finger_base_joint" type="revolute">
    <axis xyz="0 1 0"/>
    <limit effort="1000.0" lower="0.0" upper="1" velocity="0.5"/>
    <parent link="base_link"/>
    <child link="third_finger_phalanx_base"/>
    <origin xyz="0 -0.05 0.25"/>
  </joint>

  <joint name="third_finger_2_joint" type="revolute">
    <axis xyz="0 1 0"/>
    <limit effort="1000.0" lower="0.0" upper="1" velocity="0.5"/>
    <parent link="third_finger_phalanx_base"/>
    <child link="third_finger_phalanx_2"/>
    <origin xyz="0 0 0.1"/>
  </joint>

  <joint name="third_finger_3_joint" type="revolute"> 
    <axis xyz="0 1 0"/>
    <limit effort="1000.0" lower="0.0" upper="1" velocity="0.5"/>
    <parent link="third_finger_phalanx_2"/> 
    <child link="third_finger_phalanx_3"/>
    <origin xyz="0 0 0.1"/>
  </joint>

  <!--forth finger-->
  <link name="forth_finger_phalanx_base">
    <visual>
      <geometry>
        <cylinder length="0.1" radius="0.02"/>
      </geometry>
      <origin xyz="0 0 0.05"/>
      <material name="white"/>
    </visual>
  </link>

  <link name="forth_finger_phalanx_2">
    <visual>
      <geometry>
        <cylinder length="0.1" radius="0.02"/>
      </geometry>
      <material name="blue"/>
      <origin xyz="0 0.0 0.05"/>
    </visual>
  </link>

  <link name="forth_finger_phalanx_3">
    <visual>
      <geometry>
        <cylinder length="0.1" radius="0.02"/>
      </geometry>
      <material name="white"/>
      <origin xyz="0 0.0 0.05"/>
    </visual>
  </link>

  <joint name="forth_finger_base_joint" type="revolute">
    <axis xyz="0 1 0"/>
    <limit effort="1000.0" lower="0.0" upper="1" velocity="0.5"/>
    <parent link="base_link"/>
    <child link="forth_finger_phalanx_base"/>
    <origin xyz="0 -0.15 0.25"/>
  </joint>

  <joint name="forth_finger_2_joint" type="revolute">
    <axis xyz="0 1 0"/>
    <limit effort="1000.0" lower="0.0" upper="1" velocity="0.5"/>
    <parent link="forth_finger_phalanx_base"/>
    <child link="forth_finger_phalanx_2"/>
    <origin xyz="0 0 0.1"/>
  </joint>

  <joint name="forth_finger_3_joint" type="revolute"> 
    <axis xyz="0 1 0"/>
    <limit effort="1000.0" lower="0.0" upper="1" velocity="0.5"/>
    <parent link="forth_finger_phalanx_2"/> 
    <child link="forth_finger_phalanx_3"/>
    <origin xyz="0 0 0.1"/>
  </joint>

  <!--thumb-->
  <link name="thumb_phalanx_base">
    <visual>
      <geometry>
        <cylinder length="0.1" radius="0.02"/>
      </geometry>
      <origin xyz="0 0.02 0.05"/>
      <material name="white"/>
    </visual>
  </link>

  <link name="thumb_phalanx_2">
    <visual>
      <geometry>
        <cylinder length="0.1" radius="0.02"/>
      </geometry>
      <origin xyz="0 0.02 0.05"/>
      <material name="white"/>
    </visual>
  </link>

  <joint name="thumb_finger_base_joint" type="revolute">
    <axis xyz="-1 0 0"/>
    <limit effort="1000.0" lower="0.0" upper="1" velocity="0.5"/>
    <parent link="base_link"/>
    <child link="thumb_phalanx_base"/>
    <origin xyz="0 0.2 0.0" rpy="-0.8 0.5 0"/>
  </joint>

  <joint name="thumb_finger_2_joint" type="revolute">
    <axis xyz="1 0 0"/>
    <limit effort="1000.0" lower="0.0" upper="1" velocity="0.5"/>
    <parent link="thumb_phalanx_base"/>
    <child link="thumb_phalanx_2"/>
    <origin xyz="0 0 0.1"/>
  </joint>

  
</robot>
