<?xml version="1.0"?>
<robot name="spider">

  <material name="blue">
    <color rgba="0 0 0.8 1"/>
  </material>
  <material name="black">
    <color rgba="0 0 0 1"/>
  </material>
  <material name="white">
    <color rgba="1 1 1 1"/>
  </material>

  <link name="base_link">
    <visual>
      <origin rpy="0.0 0 0" xyz="0 0 1"/>
      <geometry>
        <mesh filename="package://udm_spider/mesh/torso.stl" scale="0.05 0.05 0.05"/>
      </geometry>
      <material name="white"/>
    </visual>
  </link>

  <link name="root_link_1">
    <visual>
      <origin rpy="0 0 0.7" xyz="1.0 1.0 0.6"/>
      <geometry>
        <mesh filename="package://udm_spider/mesh/rootlink.stl" scale="0.05 0.05 0.05"/>
      </geometry>
      <material name="black"/>
    </visual>
  </link>

  <joint name="root_link_1_joint" type="fixed">
    <axis xyz="0 1 0"/>
    <parent link="base_link"/>
    <child link="root_link_1"/>
    <origin xyz="0 0.17 0.25"/>
  </joint>

  <link name="long_link_1">
    <visual>
      <origin rpy="-1.5 -0.5 0.7" xyz="1.50 1.15 0.8"/>
      <geometry>
        <mesh filename="package://udm_spider/mesh/long-link.stl" scale="0.05 0.05 0.05"/>
      </geometry>
      <material name="white"/>
    </visual>
  </link>

  <joint name="long_link_1_joint" type="revolute">
    <axis xyz="0 1 0"/>
    <limit effort="1000.0" lower="0.0" upper="1" velocity="0.5"/>
    <parent link="root_link_1"/>
    <child link="long_link_1"/>
    <origin xyz="0 0.17 0.25"/>
  </joint>

  <link name="link_1">
    <visual>
      <origin rpy="1.5 0.5 0.7" xyz="2.8 2.2 1"/>
      <geometry>
        <mesh filename="package://udm_spider/mesh/link1.stl" scale="0.05 0.05 0.05"/>
      </geometry>
      <material name="black"/>
    </visual>
  </link>

  <joint name="link_1_joint" type="revolute">
    <axis xyz="0 1 0"/>
    <limit effort="1000.0" lower="0.0" upper="1" velocity="0.5"/>
    <parent link="long_link_1"/>
    <child link="link_1"/>
    <origin xyz="0 0.17 0.25"/>
  </joint>

  <link name="leaf_link_1">
    <visual>
      <origin rpy="1.5 1.5 0.7" xyz="3.2 2.4 0.25"/>
      <geometry>
        <mesh filename="package://udm_spider/mesh/leaf-link.stl" scale="0.05 0.05 0.05"/>
      </geometry>
      <material name="white"/>
    </visual>
  </link>

  <joint name="leaf_link_1_joint" type="revolute">
    <axis xyz="0 1 0"/>
    <limit effort="1000.0" lower="0.0" upper="1" velocity="0.5"/>
    <parent link="long_link_1"/>
    <child link="leaf_link_1"/>
    <origin xyz="0 0.6 5"/>
  </joint>
</robot>


